<?xml version="1.0" ?>
<!-- =================================================================================== -->
<!-- |    This document was autogenerated by xacro from g4_robot.urdf.xacro            | -->
<!-- |    EDITING THIS FILE BY HAND IS NOT RECOMMENDED                                 | -->
<!-- =================================================================================== -->
<robot name="g4_robot">
  <material name="grey">
    <color rgba="0.5 0.5 0.5 1"/>
  </material>
  <material name="green">
    <color rgba="0 0.5 0 1"/>
  </material>
  <material name="blue">
    <color rgba="0 0 1 1"/>
  </material>
  <material name="yellow">
    <color rgba="0.5 0.5 0 1"/>
  </material>
  <material name="orange">
    <color rgba="1 0.5 0 1"/>
  </material>
  <material name="red">
    <color rgba="1 0 0.2 1"/>
  </material>
  <material name="black">
    <color rgba="0 0 0 1"/>
  </material>
  <!-- body -->
  <link name="base_footprint"/>
  <link name="base_link">
    <visual>
      <geometry>
        <box size="1.0 0.7 0.3"/>
      </geometry>
      <origin rpy="0 0 0" xyz="0 0 0"/>
      <material name="green"/>
    </visual>
    <collision>
      <geometry>
        <box size="1.0 0.7 0.3"/>
      </geometry>
      <origin rpy="0 0 0" xyz="0 0 0"/>
    </collision>
    <inertial>
      <origin rpy="0 0 0" xyz="0 0 0"/>
      <mass value="25.0"/>
      <inertia ixx="9.083333333333334" ixy="0" ixz="0" iyy="12.416666666666668" iyz="0" izz="4.833333333333333"/>
    </inertial>
  </link>
  <joint name="footprint_base_joint" type="fixed">
    <parent link="base_footprint"/>
    <child link="base_link"/>
    <origin rpy="0 0 0" xyz="0 0 0.49802"/>
    <!-- + (base_h / 2) -->
  </joint>
  <!-- wheel funtions -->
  <!-- wheels creations -->
  <link name="left_wheel_link">
    <visual>
      <geometry>
        <cylinder length="0.14" radius="0.16"/>
      </geometry>
      <origin rpy="1.5707963267948966 0 0" xyz="0 0 0"/>
      <material name="blue"/>
    </visual>
    <collision>
      <geometry>
        <cylinder length="0.14" radius="0.16"/>
      </geometry>
      <origin rpy="1.5707963267948966 0 0" xyz="0 0 0"/>
    </collision>
    <inertial>
      <origin rpy="1.5707963267948966 0 0" xyz="0 0 0"/>
      <mass value="3.0"/>
      <inertia ixx="0.0964" ixy="0" ixz="0" iyy="0.0964" iyz="0" izz="0.15360000000000001"/>
    </inertial>
  </link>
  <joint name="left_wheel_joint" type="continuous">
    <parent link="base_link"/>
    <child link="left_wheel_link"/>
    <origin rpy="0 0 0" xyz="0 0.26999999999999996 -0.33802"/>
    <axis xyz="0 1 0"/>
    <limit effort="100.0" lower="-6.283185307179586" upper="6.283185307179586" velocity="100.0"/>
    <!-- random -->
    <dynamics damping="0.1" friction="0.1"/>
  </joint>
  <link name="right_wheel_link">
    <visual>
      <geometry>
        <cylinder length="0.14" radius="0.16"/>
      </geometry>
      <origin rpy="1.5707963267948966 0 0" xyz="0 0 0"/>
      <material name="blue"/>
    </visual>
    <collision>
      <geometry>
        <cylinder length="0.14" radius="0.16"/>
      </geometry>
      <origin rpy="1.5707963267948966 0 0" xyz="0 0 0"/>
    </collision>
    <inertial>
      <origin rpy="1.5707963267948966 0 0" xyz="0 0 0"/>
      <mass value="3.0"/>
      <inertia ixx="0.0964" ixy="0" ixz="0" iyy="0.0964" iyz="0" izz="0.15360000000000001"/>
    </inertial>
  </link>
  <joint name="right_wheel_joint" type="continuous">
    <parent link="base_link"/>
    <child link="right_wheel_link"/>
    <origin rpy="0 0 0" xyz="0 -0.26999999999999996 -0.33802"/>
    <axis xyz="0 1 0"/>
    <limit effort="100.0" lower="-6.283185307179586" upper="6.283185307179586" velocity="100.0"/>
    <!-- random -->
    <dynamics damping="0.1" friction="0.1"/>
  </joint>
  <!-- Front -->
  <link name="front_hinge">
    <visual>
      <geometry>
        <cylinder length="0.28502" radius="0.02"/>
      </geometry>
      <origin rpy="0 0 0" xyz="0 0 0.14251"/>
      <material name="grey"/>
    </visual>
    <collision>
      <geometry>
        <cylinder length="0.28502" radius="0.02"/>
      </geometry>
      <origin rpy="0 0 0" xyz="0 0 0.14251"/>
    </collision>
    <inertial>
      <origin rpy="0 0 0" xyz="0 0 0.14251"/>
      <mass value="0.5"/>
      <inertia ixx="0.013739400066666666" ixy="0" ixz="0" iyy="0.013739400066666666" iyz="0" izz="0.0004"/>
    </inertial>
  </link>
  <joint name="front_hinge_joint" type="continuous">
    <parent link="base_link"/>
    <child link="front_hinge"/>
    <origin rpy="0 0 0" xyz="0.48 0 -0.43501999999999996"/>
    <axis xyz="0 0 1"/>
  </joint>
  <link name="front_wheel_link">
    <visual>
      <geometry>
        <cylinder length="0.028" radius="0.063"/>
      </geometry>
      <origin rpy="1.5707963267948966 0 0" xyz="0 0 0"/>
      <material name="blue"/>
    </visual>
    <collision>
      <geometry>
        <cylinder length="0.028" radius="0.063"/>
      </geometry>
      <origin rpy="1.5707963267948966 0 0" xyz="0 0 0"/>
    </collision>
    <inertial>
      <origin rpy="1.5707963267948966 0 0" xyz="0 0 0"/>
      <mass value="1.5"/>
      <inertia ixx="0.0063455000000000004" ixy="0" ixz="0" iyy="0.0063455000000000004" iyz="0" izz="0.011907000000000001"/>
    </inertial>
  </link>
  <joint name="front_wheel_joint" type="continuous">
    <parent link="front_hinge"/>
    <child link="front_wheel_link"/>
    <origin rpy="0 0 0" xyz="-0.03 0 0"/>
    <axis xyz="0 1 0"/>
  </joint>
  <!-- Rear -->
  <link name="rear_hinge">
    <visual>
      <geometry>
        <cylinder length="0.28502" radius="0.02"/>
      </geometry>
      <origin rpy="0 0 0" xyz="0 0 0.14251"/>
      <material name="grey"/>
    </visual>
    <collision>
      <geometry>
        <cylinder length="0.28502" radius="0.02"/>
      </geometry>
      <origin rpy="0 0 0" xyz="0 0 0.14251"/>
    </collision>
    <inertial>
      <origin rpy="0 0 0" xyz="0 0 0.14251"/>
      <mass value="0.5"/>
      <inertia ixx="0.013739400066666666" ixy="0" ixz="0" iyy="0.013739400066666666" iyz="0" izz="0.0004"/>
    </inertial>
  </link>
  <joint name="rear_hinge_joint" type="continuous">
    <parent link="base_link"/>
    <child link="rear_hinge"/>
    <origin rpy="0 0 0" xyz="-0.48 0 -0.43501999999999996"/>
    <axis xyz="0 0 1"/>
  </joint>
  <link name="rear_wheel_link">
    <visual>
      <geometry>
        <cylinder length="0.028" radius="0.063"/>
      </geometry>
      <origin rpy="1.5707963267948966 0 0" xyz="0 0 0"/>
      <material name="blue"/>
    </visual>
    <collision>
      <geometry>
        <cylinder length="0.028" radius="0.063"/>
      </geometry>
      <origin rpy="1.5707963267948966 0 0" xyz="0 0 0"/>
    </collision>
    <inertial>
      <origin rpy="1.5707963267948966 0 0" xyz="0 0 0"/>
      <mass value="1.5"/>
      <inertia ixx="0.0063455000000000004" ixy="0" ixz="0" iyy="0.0063455000000000004" iyz="0" izz="0.011907000000000001"/>
    </inertial>
  </link>
  <joint name="rear_wheel_joint" type="continuous">
    <parent link="rear_hinge"/>
    <child link="rear_wheel_link"/>
    <origin rpy="0 0 0" xyz="-0.03 0 0"/>
    <axis xyz="0 1 0"/>
  </joint>
  <!-- camera -->
  <link name="camera_link">
    <visual>
      <geometry>
        <box size="0.01 0.1 0.05"/>
      </geometry>
      <origin rpy="0 0 0" xyz="-0.005 0 0"/>
      <material name="red"/>
    </visual>
    <collision>
      <geometry>
        <box size="0.01 0.1 0.05"/>
      </geometry>
      <origin rpy="0 0 0" xyz="-0.005 0 0"/>
    </collision>
    <inertial>
      <origin rpy="0 0 0" xyz="0 0 0"/>
      <mass value="0.1"/>
      <inertia ixx="2.166666666666667e-05" ixy="0" ixz="0" iyy="8.416666666666668e-05" iyz="0" izz="0.00010416666666666669"/>
    </inertial>
  </link>
  <joint name="base_camera_joint" type="fixed">
    <parent link="base_link"/>
    <child link="camera_link"/>
    <origin rpy="0 0 0" xyz="0.51 0 0.125"/>
  </joint>
  <!--               camera for sensors                -->
  <!-- <link name="camera_link_optical" />

    <joint name="camera_optical_joint" type="fixed">
    
    <origin xyz="0 0 0" rpy="${-pi/2} 0 ${-pi/2}"/>
    <parent link="camera_link"/>
    <child link="camera_link_optical"/>
    </joint> -->
  <!-- these values have to be these values otherwise the gazebo camera
        image won't be aligned properly with the frame it is supposedly
        originating from -->
  <!-- <xacro:property name="initial_positions" value="${xacro.load_yaml(initial_positions_file)['initial_positions']}"/> -->
  <transmission name="right_wheel_trans">
    <type>transmission_interface/SimpleTransmission</type>
    <joint name="right_wheel_joint">
      <hardwareInterface>hardware_interface/VelocityJointInterface</hardwareInterface>
    </joint>
    <actuator name="right_wheel_motor">
      <mechanicalReduction>1</mechanicalReduction>
    </actuator>
  </transmission>
  <transmission name="left_wheel_trans">
    <type>transmission_interface/SimpleTransmission</type>
    <joint name="left_wheel_joint">
      <hardwareInterface>hardware_interface/VelocityJointInterface</hardwareInterface>
    </joint>
    <actuator name="left_wheel_motor">
      <mechanicalReduction>1</mechanicalReduction>
    </actuator>
  </transmission>
  <ros2_control name="IsaacSimSystem" type="system">
    <hardware>
      <!-- Leave UNcommented ONLY the plugin you WANT to use -->
      <!-- If using a ros2_control_hardware_type 'mock_components' - leave uncomment -->
      <!-- <plugin>mock_components/GenericSystem</plugin> -->
      <!-- If using a ros2_control_hardware_type 'isaac' - leave uncomment -->
      <!-- first option is simple system perfect conrtrol -->
      <!-- <plugin>mock_components/GenericSystem</plugin> -->
      <!-- second option is topic based when not supporting connection to hardware -->
      <plugin>topic_based_ros2_control/TopicBasedSystem</plugin>
      <param name="joint_commands_topic">/isaac_joint_commands</param>
      <param name="joint_states_topic">/isaac_joint_states</param>
      <param name="sum_wrapped_joint_states">false</param>
      <!-- counts number of wraps (turns) the wheel made -->
    </hardware>
    <joint name="right_wheel_joint">
      <command_interface name="velocity">
        <param name="min">-10</param>
        <param name="max">10</param>
      </command_interface>
      <state_interface name="velocity">
        <param name="initial_value">0.0</param>
      </state_interface>
      <state_interface name="position">
        <param name="initial_value">0.0</param>
      </state_interface>
    </joint>
    <joint name="left_wheel_joint">
      <command_interface name="velocity">
        <param name="min">-10</param>
        <param name="max">10</param>
      </command_interface>
      <state_interface name="velocity">
        <param name="initial_value">0.0</param>
      </state_interface>
      <state_interface name="position">
        <param name="initial_value">0.0</param>
      </state_interface>
    </joint>
  </ros2_control>
  <!--   Lidar        -->
  <link name="lidar_link">
    <visual>
      <geometry>
        <cylinder length="0.04" radius="0.05"/>
      </geometry>
      <material name="black"/>
    </visual>
    <collision>
      <geometry>
        <cylinder length="0.04" radius="0.05"/>
      </geometry>
    </collision>
    <inertial>
      <origin rpy="0 0 0" xyz="0 0 0"/>
      <mass value="0.1"/>
      <inertia ixx="0.0003033333333333334" ixy="0" ixz="0" iyy="0.0003033333333333334" iyz="0" izz="0.0005000000000000001"/>
    </inertial>
  </link>
  <joint name="base_lidar_joint" type="fixed">
    <parent link="base_link"/>
    <child link="lidar_link"/>
    <origin rpy="0 0 0" xyz="0.25 0 0.16999999999999998"/>
  </joint>
  <!-- ${-(pi) / 12.0 * 11} = -2.87979327-->
  <!-- <xacro:include filename="lidar_gazebo.xacro" /> -->
  <!-- <xacro:include filename="camera.xacro" /> -->
  <!-- <xacro:include filename="camera_gazebo.xacro" /> -->
</robot>
