<?xml version="1.0" ?>
<!-- =================================================================================== -->
<!-- |    This document was autogenerated by xacro from g3_robot.urdf.xacro            | -->
<!-- |    EDITING THIS FILE BY HAND IS NOT RECOMMENDED                                 | -->
<!-- =================================================================================== -->
<robot name="g3_robot">

  <material name="grey">
    <color rgba="0.5 0.5 0.5 1"/>
  </material>
  <material name="green">
    <color rgba="0 0.5 0 1"/>
  </material>
  <material name="blue">
    <color rgba="0 0 1 1"/>
  </material>
  <material name="yellow">
    <color rgba="0.5 0.5 0 1"/>
  </material>
  <material name="orange">
    <color rgba="1 0.5 0 1"/>
  </material>
  <material name="red">
    <color rgba="1 0 0.2 1"/>
  </material>
  <material name="black">
    <color rgba="0 0 0 1"/>
  </material>

  <!-- body -->
  <link name="base_footprint"/>

  <link name="base_link">
    <visual>
      <geometry>
        <box size="1.0 0.6 0.4"/>
      </geometry>
      <origin rpy="0 0 0" xyz="0 0 0"/>
      <material name="green"/>
    </visual>
    <collision>
      <geometry>
        <box size="1.0 0.6 0.4"/>
      </geometry>
      <origin rpy="0 0 0" xyz="0 0 0"/>
    </collision>
    <inertial>
      <origin rpy="0 0 0" xyz="0 0 0"/>
      <mass value="25.0"/>
      <inertia ixx="9.666666666666668" ixy="0" ixz="0" iyy="11.333333333333334" iyz="0" izz="4.333333333333334"/>
    </inertial>
  </link>

  <joint name="footprint_base_joint" type="fixed">
    <parent link="base_footprint"/>
    <child link="base_link"/>
    <origin rpy="0 0 0" xyz="0 0 0.36"/>
    
  </joint>

  
  <!-- wheels creations -->
  <link name="left_wheel_link">
    <visual>
      <geometry>
        <cylinder length="0.14" radius="0.16"/>
      </geometry>
      <origin rpy="1.5707963267948966 0 0" xyz="0 0 0"/>
      <material name="blue"/>
    </visual>
    <collision>
      <geometry>
        <cylinder length="0.14" radius="0.16"/>
      </geometry>
      <origin rpy="1.5707963267948966 0 0" xyz="0 0 0"/>
    </collision>
    <inertial>
      <origin rpy="1.5707963267948966 0 0" xyz="0 0 0"/>
      <mass value="3.0"/>
      <inertia ixx="0.0964" ixy="0" ixz="0" iyy="0.0964" iyz="0" izz="0.15360000000000001"/>
    </inertial>
  </link>

  <joint name="left_wheel_joint" type="continuous">
    <parent link="base_link"/>
    <child link="left_wheel_link"/>
    <origin rpy="0 0 0" xyz="0 0.3 -0.2"/>
    <axis xyz="0 1 0"/>
    <!-- <limit effort="100.0" velocity="100.0"/> -->
    <!-- <dynamics damping="10.0" friction="10.0" /> that's actually a lot prettyh sure -->
    <dynamics damping="1000" friction="10.0" />
  </joint>

  <link name="right_wheel_link">
    <visual>
      <geometry>
        <cylinder length="0.14" radius="0.16"/>
      </geometry>
      <origin rpy="1.5707963267948966 0 0" xyz="0 0 0"/>
      <material name="blue"/>
    </visual>
    <collision>
      <geometry>
        <cylinder length="0.14" radius="0.16"/>
      </geometry>
      <origin rpy="1.5707963267948966 0 0" xyz="0 0 0"/>
    </collision>
    <inertial>
      <origin rpy="1.5707963267948966 0 0" xyz="0 0 0"/>
      <mass value="3.0"/>
      <inertia ixx="0.0964" ixy="0" ixz="0" iyy="0.0964" iyz="0" izz="0.15360000000000001"/>
    </inertial>
  </link>

  <joint name="right_wheel_joint" type="continuous">
    <parent link="base_link"/>
    <child link="right_wheel_link"/>
    <origin rpy="0 0 0" xyz="0 -0.3 -0.2"/>
    <axis xyz="0 1 0"/>
    <dynamics damping="1000" friction="10.0" />
  </joint>

  <link name="front_hinge">
    <visual>
      <geometry>
        <cylinder length="0.11" radius="0.021"/>
      </geometry>
      <origin rpy="0 0 0" xyz="0 0 0.055"/>
      <material name="grey"/>
    </visual>
    <collision>
      <geometry>
        <cylinder length="0.11" radius="0.03150000000000001"/>
      </geometry>
      <origin rpy="0 0 0" xyz="0 0 0.055"/>
    </collision>
    <inertial>
      <origin rpy="0 0 0" xyz="0 0 0.055"/>
      <mass value="0.5"/>
      <inertia ixx="0.0025127916666666666" ixy="0" ixz="0" iyy="0.0025127916666666666" iyz="0" izz="0.0009922500000000005"/>
    </inertial>
  </link>

  <joint name="front_hinge_joint" type="continuous">
    <parent link="base_link"/>
    <child link="front_hinge"/>
    <origin rpy="0 0 0" xyz="0.4 0 -0.31"/>
    <axis xyz="0 0 1"/>
    <!-- <dynamics damping="0.0000000001" friction="10.0" /> -->
  </joint>

  <link name="front_wheel_link">
    <visual>
      <geometry>
        <cylinder length="0.07" radius="0.05"/>
      </geometry>
      <origin rpy="1.5707963267948966 0 0" xyz="0 0 0"/>
      <material name="blue"/>
    </visual>
    <collision>
      <geometry>
        <cylinder length="0.07" radius="0.05"/>
      </geometry>
      <origin rpy="1.5707963267948966 0 0" xyz="0 0 0"/>
    </collision>
    <inertial>
      <origin rpy="1.5707963267948966 0 0" xyz="0 0 0"/>
      <mass value="1.5"/>
      <inertia ixx="0.006200000000000001" ixy="0" ixz="0" iyy="0.006200000000000001" iyz="0" izz="0.0075000000000000015"/>
    </inertial>
  </link>

  <joint name="front_wheel_joint" type="continuous">
    <parent link="front_hinge"/>
    <child link="front_wheel_link"/>
    <origin rpy="0 0 0" xyz="0 0 0"/>
    <axis xyz="0 1 0"/>
    <!-- <dynamics damping="0.0000000001" friction="1000.0" /> -->
  </joint>

  <link name="rear_hinge">
    <visual>
      <geometry>
        <cylinder length="0.11" radius="0.021"/>
      </geometry>
      <origin rpy="0 0 0" xyz="0 0 0.055"/>
      <material name="grey"/>
    </visual>
    <collision>
      <geometry>
        <cylinder length="0.11" radius="0.03150000000000001"/>
      </geometry>
      <origin rpy="0 0 0" xyz="0 0 0.055"/>
    </collision>
    <inertial>
      <origin rpy="0 0 0" xyz="0 0 0.055"/>
      <mass value="0.5"/>
      <inertia ixx="0.0025127916666666666" ixy="0" ixz="0" iyy="0.0025127916666666666" iyz="0" izz="0.0009922500000000005"/>
    </inertial>
  </link>

  <joint name="rear_hinge_joint" type="continuous">
    <parent link="base_link"/>
    <child link="rear_hinge"/>
    <origin rpy="0 0 0" xyz="-0.4 0 -0.31"/>
    <axis xyz="0 0 1"/>
    <!-- <dynamics damping="0.0000000001" friction="10.0" /> -->
  </joint>

  <link name="rear_wheel_link">
    <visual>
      <geometry>
        <cylinder length="0.07" radius="0.05"/>
      </geometry>
      <origin rpy="1.5707963267948966 0 0" xyz="0 0 0"/>
      <material name="blue"/>
    </visual>
    <collision>
      <geometry>
        <cylinder length="0.07" radius="0.05"/>
      </geometry>
      <origin rpy="1.5707963267948966 0 0" xyz="0 0 0"/>
    </collision>
    <inertial>
      <origin rpy="1.5707963267948966 0 0" xyz="0 0 0"/>
      <mass value="1.5"/>
      <inertia ixx="0.006200000000000001" ixy="0" ixz="0" iyy="0.006200000000000001" iyz="0" izz="0.0075000000000000015"/>
    </inertial>
  </link>

  <joint name="rear_wheel_joint" type="continuous">
    <parent link="rear_hinge"/>
    <child link="rear_wheel_link"/>
    <origin rpy="0 0 0" xyz="0 0 0"/>
    <axis xyz="0 1 0"/>
    <!-- <dynamics damping="0.0000000001" friction="1000.0" /> -->
  </joint>

  <!--                         camera                    -->

  <link name="camera_link">
    <visual>
      <geometry>
        <box size="0.01 0.1 0.05"/>
      </geometry>
      <origin rpy="0 0 0" xyz="-0.005 0 0"/>
      <material name="red"/>
    </visual>
    <collision>
      <geometry>
        <box size="0.01 0.1 0.05"/>
      </geometry>
      <origin rpy="0 0 0" xyz="-0.005 0 0"/>
    </collision>
    <inertial>
      <origin rpy="0 0 0" xyz="0 0 0"/>
      <mass value="0.1"/>
      <inertia ixx="2.166666666666667e-05" ixy="0" ixz="0" iyy="8.416666666666668e-05" iyz="0" izz="0.00010416666666666669"/>
    </inertial>
  </link>

  <joint name="base_camera_joint" type="fixed">
    <parent link="base_link"/>
    <child link="camera_link"/>
    <origin rpy="0 0 0" xyz="0.51 0 0.17500000000000002"/>
  </joint>
  
  <!--                    Lidar                  -->

  <link name="lidar_link">
    <visual>
      <geometry>
        <cylinder length="0.04" radius="0.05"/>
      </geometry>
      <origin rpy="0 0 0" xyz="0 0 0"/>
      <material name="black"/>
    </visual>
    <collision>
      <geometry>
        <cylinder length="0.04" radius="0.05"/>
      </geometry>
      <origin rpy="0 0 0" xyz="0 0 0"/>
    </collision>
    <inertial>
      <origin rpy="0 0 0" xyz="0 0 0"/>
      <mass value="0.1"/>
      <inertia ixx="0.0003033333333333334" ixy="0" ixz="0" iyy="0.0003033333333333334" iyz="0" izz="0.0005000000000000001"/>
    </inertial>
  </link>

  <joint name="base_lidar_joint" type="fixed">
    <parent link="base_link"/>
    <child link="lidar_link"/>
    <origin rpy="0 0 0" xyz="0.25 0 0.22"/>
  </joint>

</robot>
